<mujoco model="swimmer">
  <include file="./common/visual.xml"/>
  <include file="./common/skybox.xml"/>
  <include file="./common/materials.xml"/>

  <option timestep="0.002" density="3000">
    <flag contact="disable"/>
  </option>

  <default>
    <default class="swimmer">
      <joint type="hinge" pos="0 -.05 0" axis="0 0 1" limited="true" solreflimit=".05 1" solimplimit="0 .8 .1" armature="1e-6"/>
      <default class="inertial">
        <geom type="box" size=".001 .05 .01" rgba="0 0 0 0" mass=".01"/>
      </default>
      <default class="visual">
        <geom type="capsule" size=".01" fromto="0 -.05 0 0 .05 0" material="self" mass="0"/>
      </default>
      <site size=".01" rgba="0 0 0 0"/>
    </default>
    <default class="free">
      <joint limited="false" stiffness="0" armature="0"/>
    </default>
    <motor gear="5e-4" ctrllimited="true" ctrlrange="-1 1"/>
  </default>

  <worldbody>
    <geom name="ground" type="plane" size="2 2 0.1" material="grid"/>

    <!-- Swimmer One -->
    <body name="head1" pos="0 0 .05" childclass="swimmer">
      <light name="light1_1" diffuse=".8 .8 .8" pos="0 0 1.5"/>
      <geom name="head1" type="ellipsoid" size=".02 .04 .017" pos="0 -.022 0"  material="self" mass="0"/>
      <geom name="nose1" type="sphere" pos="0 -.06 0" size=".004" material="effector" mass="0"/>
      <geom name="eyes1" type="capsule" fromto="-.006 -.054 .005 .006 -.054 .005" size=".004" material="eye" mass="0"/>
      <camera name="tracking11" pos="0 -.2 .5" xyaxes="1 0 0 0 1 1" mode="trackcom" fovy="60"/>
      <camera name="tracking12" pos="-.9 .5 .15" xyaxes="0 -1 0 .3 0 1" mode="trackcom" fovy="60"/>
      <camera name="eyes1" pos="0 -.058 .005" xyaxes="-1 0 0 0 0 1"/>
      <joint name="rootx1" class="free" type="slide" axis="1 0 0" pos="0 -.05 0"/>
      <joint name="rooty1" class="free" type="slide" axis="0 1 0" pos="0 -.05 0"/>
      <joint name="rootz1" class="free" type="hinge" axis="0 0 1" pos="0 -.05 0"/>
      <geom name="inertial1" class="inertial"/>
      <geom name="visual1" class="visual"/>
      <site name="head1"/>
    </body>

    <!-- Swimmer Two -->
    <body name="head2" pos="0 0.5 .05" childclass="swimmer">
      <light name="light2_1" diffuse=".8 .8 .8" pos="0 0 1.5"/>
      <geom name="head2" type="ellipsoid" size=".02 .04 .017" pos="0 -.022 0"  material="self" mass="0"/>
      <geom name="nose2" type="sphere" pos="0 -.06 0" size=".004" material="effector" mass="0"/>
      <geom name="eyes2" type="capsule" fromto="-.006 -.054 .005 .006 -.054 .005" size=".004" material="eye" mass="0"/>
      <camera name="tracking21" pos="0 -.2 .5" xyaxes="1 0 0 0 1 1" mode="trackcom" fovy="60"/>
      <camera name="tracking22" pos="-.9 .5 .15" xyaxes="0 -1 0 .3 0 1" mode="trackcom" fovy="60"/>
      <camera name="eyes2" pos="0 -.058 .005" xyaxes="-1 0 0 0 0 1"/>
      <joint name="rootx2" class="free" type="slide" axis="1 0 0" pos="0 -.05 0"/>
      <joint name="rooty2" class="free" type="slide" axis="0 1 0" pos="0 -.05 0"/>
      <joint name="rootz2" class="free" type="hinge" axis="0 0 1" pos="0 -.05 0"/>
      <geom name="inertial2" class="inertial"/>
      <geom name="visual2" class="visual"/>
      <site name="head2"/>
    </body>

    <geom name="target" type="sphere" pos="1 1 .05" size=".1" material="target"/>
    <light name="target_light" diffuse="1 1 1" pos="1 1 1.5"/>
  </worldbody>

  <sensor>
    <framepos name="nose1_pos" objtype="geom" objname="nose1"/>
    <framepos name="target_pos" objtype="geom" objname="target"/>
    <framexaxis name="head1_xaxis" objtype="xbody" objname="head1"/>
    <frameyaxis name="head1_yaxis" objtype="xbody" objname="head1"/>
    <velocimeter name="head1_vel" site="head1"/>
    <gyro name="head1_gyro" site="head1"/>
  </sensor>

</mujoco>
